{
 "cells": [
  {
   "cell_type": "code",
   "execution_count": 7,
   "id": "3c1f9c43",
   "metadata": {},
   "outputs": [],
   "source": [
    "# Create a practice set of random latitude and longitude combinations."
   ]
  },
  {
   "cell_type": "code",
   "execution_count": 12,
   "id": "77c7ad8e",
   "metadata": {},
   "outputs": [],
   "source": [
    "x = [25.12903645, 25.92017388, 26.62509167, -59.98969384, 37.30571269]\n",
    "y = [-67.59741259, 11.09532135, 74.84233102, -76.89176677, -61.13376282]\n",
    "coordinates = zip(x, y)"
   ]
  },
  {
   "cell_type": "code",
   "execution_count": 13,
   "id": "ac873335",
   "metadata": {},
   "outputs": [
    {
     "name": "stdout",
     "output_type": "stream",
     "text": [
      "25.12903645 -67.59741259\n",
      "25.92017388 11.09532135\n",
      "26.62509167 74.84233102\n",
      "-59.98969384 -76.89176677\n",
      "37.30571269 -61.13376282\n"
     ]
    }
   ],
   "source": [
    "# Use the tuple() function to display the latitude and longitude combinations.\n",
    "for coordinate in coordinates:\n",
    "    print(coordinate[0], coordinate[1])"
   ]
  },
  {
   "cell_type": "code",
   "execution_count": 14,
   "id": "dee07de1",
   "metadata": {},
   "outputs": [],
   "source": [
    "# Use the citipy module to determine city based on latitude and longitude.\n",
    "from citipy import citipy"
   ]
  },
  {
   "cell_type": "code",
   "execution_count": 15,
   "id": "6e441886",
   "metadata": {},
   "outputs": [],
   "source": [
    "# Use the tuple() function to display the latitude and longitude combinations.\n",
    "for coordinate in coordinates:\n",
    "    print(citipy.nearest_city(coordinate[0], coordinate[1]).city_name,\n",
    "          citipy.nearest_city(coordinate[0], coordinate[1]).country_code)"
   ]
  },
  {
   "cell_type": "code",
   "execution_count": 16,
   "id": "a06747f0",
   "metadata": {},
   "outputs": [],
   "source": [
    "# Import the requests library.\n",
    "import requests\n",
    "\n",
    "# Import the API key.\n",
    "from config import weather_api_key"
   ]
  },
  {
   "cell_type": "code",
   "execution_count": 18,
   "id": "7bb7bca3",
   "metadata": {},
   "outputs": [
    {
     "name": "stdout",
     "output_type": "stream",
     "text": [
      "http://api.openweathermap.org/data/2.5/weather?units=Imperial&APPID=6a22f88d5ece10e7f219cdebaffffc5e\n"
     ]
    }
   ],
   "source": [
    "# Starting URL for Weather Map API Call.\n",
    "url = \"http://api.openweathermap.org/data/2.5/weather?units=Imperial&APPID=\" + weather_api_key\n",
    "print(url)"
   ]
  },
  {
   "cell_type": "code",
   "execution_count": 19,
   "id": "23d19a7e",
   "metadata": {},
   "outputs": [
    {
     "name": "stdout",
     "output_type": "stream",
     "text": [
      "http://api.openweathermap.org/data/2.5/weather?units=Imperial&APPID=6a22f88d5ece10e7f219cdebaffffc5e&q=Boston\n"
     ]
    }
   ],
   "source": [
    "# Create an endpoint URL for a city.\n",
    "city_url = url + \"&q=\" + \"Boston\"\n",
    "print(city_url)"
   ]
  },
  {
   "cell_type": "code",
   "execution_count": 20,
   "id": "6bff71fb",
   "metadata": {},
   "outputs": [
    {
     "data": {
      "text/plain": [
       "<Response [200]>"
      ]
     },
     "execution_count": 20,
     "metadata": {},
     "output_type": "execute_result"
    }
   ],
   "source": [
    "# Make a 'Get' request for the city weather.\n",
    "city_weather = requests.get(city_url)\n",
    "city_weather"
   ]
  },
  {
   "cell_type": "code",
   "execution_count": 21,
   "id": "95e67614",
   "metadata": {},
   "outputs": [
    {
     "data": {
      "text/plain": [
       "<Response [404]>"
      ]
     },
     "execution_count": 21,
     "metadata": {},
     "output_type": "execute_result"
    }
   ],
   "source": [
    "# Create an endpoint URL for a city.\n",
    "city_url = url + \"&q=\" + \"Bston\"\n",
    "city_weather = requests.get(city_url)\n",
    "city_weather"
   ]
  },
  {
   "cell_type": "code",
   "execution_count": 22,
   "id": "ca06018a",
   "metadata": {},
   "outputs": [
    {
     "data": {
      "text/plain": [
       "<Response [200]>"
      ]
     },
     "execution_count": 22,
     "metadata": {},
     "output_type": "execute_result"
    }
   ],
   "source": [
    "# Create an endpoint URL for a city.\n",
    "city_url = url + \"&q=\" + \"Boston\"\n",
    "city_weather = requests.get(city_url)\n",
    "city_weather"
   ]
  },
  {
   "cell_type": "code",
   "execution_count": 23,
   "id": "a96919d5",
   "metadata": {},
   "outputs": [
    {
     "data": {
      "text/plain": [
       "'{\"coord\":{\"lon\":-71.0598,\"lat\":42.3584},\"weather\":[{\"id\":801,\"main\":\"Clouds\",\"description\":\"few clouds\",\"icon\":\"02n\"}],\"base\":\"stations\",\"main\":{\"temp\":27.59,\"feels_like\":22.98,\"temp_min\":25.61,\"temp_max\":29.48,\"pressure\":1018,\"humidity\":57},\"visibility\":10000,\"wind\":{\"speed\":4,\"deg\":338,\"gust\":15.01},\"clouds\":{\"all\":20},\"dt\":1637726603,\"sys\":{\"type\":2,\"id\":2013408,\"country\":\"US\",\"sunrise\":1637667913,\"sunset\":1637702196},\"timezone\":-18000,\"id\":4930956,\"name\":\"Boston\",\"cod\":200}'"
      ]
     },
     "execution_count": 23,
     "metadata": {},
     "output_type": "execute_result"
    }
   ],
   "source": [
    "# Get the text of the 'Get' request.\n",
    "city_weather.text"
   ]
  },
  {
   "cell_type": "code",
   "execution_count": 24,
   "id": "f9e85f54",
   "metadata": {},
   "outputs": [
    {
     "data": {
      "text/plain": [
       "{'coord': {'lon': -71.0598, 'lat': 42.3584},\n",
       " 'weather': [{'id': 801,\n",
       "   'main': 'Clouds',\n",
       "   'description': 'few clouds',\n",
       "   'icon': '02n'}],\n",
       " 'base': 'stations',\n",
       " 'main': {'temp': 27.59,\n",
       "  'feels_like': 22.98,\n",
       "  'temp_min': 25.61,\n",
       "  'temp_max': 29.48,\n",
       "  'pressure': 1018,\n",
       "  'humidity': 57},\n",
       " 'visibility': 10000,\n",
       " 'wind': {'speed': 4, 'deg': 338, 'gust': 15.01},\n",
       " 'clouds': {'all': 20},\n",
       " 'dt': 1637726603,\n",
       " 'sys': {'type': 2,\n",
       "  'id': 2013408,\n",
       "  'country': 'US',\n",
       "  'sunrise': 1637667913,\n",
       "  'sunset': 1637702196},\n",
       " 'timezone': -18000,\n",
       " 'id': 4930956,\n",
       " 'name': 'Boston',\n",
       " 'cod': 200}"
      ]
     },
     "execution_count": 24,
     "metadata": {},
     "output_type": "execute_result"
    }
   ],
   "source": [
    "# Get the JSON text of the 'Get' request.\n",
    "city_weather.json()"
   ]
  },
  {
   "cell_type": "code",
   "execution_count": 25,
   "id": "3a751915",
   "metadata": {},
   "outputs": [
    {
     "name": "stdout",
     "output_type": "stream",
     "text": [
      "City Weather found.\n"
     ]
    }
   ],
   "source": [
    "# Create an endpoint URL for a city.\n",
    "city_url = url + \"&q=\" + \"Boston\"\n",
    "city_weather = requests.get(city_url)\n",
    "if city_weather.status_code == 200:\n",
    "    print(f\"City Weather found.\")\n",
    "else:\n",
    "    print(f\"City weather not found.\")"
   ]
  },
  {
   "cell_type": "code",
   "execution_count": 26,
   "id": "7c53ed00",
   "metadata": {},
   "outputs": [
    {
     "data": {
      "text/plain": [
       "{'coord': {'lon': -71.0598, 'lat': 42.3584},\n",
       " 'weather': [{'id': 801,\n",
       "   'main': 'Clouds',\n",
       "   'description': 'few clouds',\n",
       "   'icon': '02n'}],\n",
       " 'base': 'stations',\n",
       " 'main': {'temp': 27.59,\n",
       "  'feels_like': 18.84,\n",
       "  'temp_min': 25.57,\n",
       "  'temp_max': 29.23,\n",
       "  'pressure': 1018,\n",
       "  'humidity': 57},\n",
       " 'visibility': 10000,\n",
       " 'wind': {'speed': 8.99, 'deg': 327, 'gust': 18.01},\n",
       " 'clouds': {'all': 20},\n",
       " 'dt': 1637728516,\n",
       " 'sys': {'type': 2,\n",
       "  'id': 2013408,\n",
       "  'country': 'US',\n",
       "  'sunrise': 1637667913,\n",
       "  'sunset': 1637702196},\n",
       " 'timezone': -18000,\n",
       " 'id': 4930956,\n",
       " 'name': 'Boston',\n",
       " 'cod': 200}"
      ]
     },
     "execution_count": 26,
     "metadata": {},
     "output_type": "execute_result"
    }
   ],
   "source": [
    "# Create an endpoint URL for a city.\n",
    "city_url = url + \"&q=\" + \"Boston\"\n",
    "city_weather = requests.get(city_url)\n",
    "city_weather.json()"
   ]
  },
  {
   "cell_type": "code",
   "execution_count": 34,
   "id": "005fc094",
   "metadata": {},
   "outputs": [
    {
     "name": "stdout",
     "output_type": "stream",
     "text": [
      "42.3584 -71.0598 29.23 57 20 8.99\n"
     ]
    }
   ],
   "source": [
    "# Get the JSON data.\n",
    "boston_data = city_weather.json()\n",
    "lat = boston_data[\"coord\"][\"lat\"]\n",
    "lng = boston_data[\"coord\"][\"lon\"]\n",
    "max_temp = boston_data[\"main\"][\"temp_max\"]\n",
    "humidity = boston_data[\"main\"][\"humidity\"]\n",
    "clouds = boston_data[\"clouds\"][\"all\"]\n",
    "wind = boston_data[\"wind\"][\"speed\"]\n",
    "print(lat, lng, max_temp, humidity, clouds, wind)"
   ]
  },
  {
   "cell_type": "code",
   "execution_count": 39,
   "id": "d4d4e1e3",
   "metadata": {},
   "outputs": [
    {
     "data": {
      "text/plain": [
       "'2021-11-24 04:35:16'"
      ]
     },
     "execution_count": 39,
     "metadata": {},
     "output_type": "execute_result"
    }
   ],
   "source": [
    "# Import the datetime module from the datetime library.\n",
    "from datetime import datetime\n",
    "# Get the date from the JSON file.\n",
    "date = boston_data[\"dt\"]\n",
    "# Convert the UTC date to a date format with year, month, day, hours, minutes, and seconds.\n",
    "datetime.utcfromtimestamp(date).strftime('%Y-%m-%d %H:%M:%S')"
   ]
  },
  {
   "cell_type": "code",
   "execution_count": null,
   "id": "8fc532c8",
   "metadata": {},
   "outputs": [
    {
     "name": "stderr",
     "output_type": "stream",
     "text": [
      "ERROR:root:Internal Python error in the inspect module.\n",
      "Below is the traceback from this internal error.\n",
      "\n",
      "ERROR:root:Internal Python error in the inspect module.\n",
      "Below is the traceback from this internal error.\n",
      "\n",
      "ERROR:root:Internal Python error in the inspect module.\n",
      "Below is the traceback from this internal error.\n",
      "\n"
     ]
    },
    {
     "name": "stdout",
     "output_type": "stream",
     "text": [
      "Traceback (most recent call last):\n",
      "  File \"/Users/mosi/opt/anaconda3/lib/python3.8/site-packages/IPython/core/interactiveshell.py\", line 3437, in run_code\n",
      "    exec(code_obj, self.user_global_ns, self.user_ns)\n",
      "  File \"<ipython-input-40-40f591368024>\", line 2, in <module>\n",
      "    lats = np.random.uniform(low=-90.000, high=90.000, size=1500)\n",
      "NameError: name 'np' is not defined\n",
      "\n",
      "During handling of the above exception, another exception occurred:\n",
      "\n",
      "Traceback (most recent call last):\n",
      "  File \"/Users/mosi/opt/anaconda3/lib/python3.8/site-packages/IPython/core/interactiveshell.py\", line 2061, in showtraceback\n",
      "    stb = value._render_traceback_()\n",
      "AttributeError: 'NameError' object has no attribute '_render_traceback_'\n",
      "\n",
      "During handling of the above exception, another exception occurred:\n",
      "\n",
      "Traceback (most recent call last):\n",
      "  File \"/Users/mosi/opt/anaconda3/lib/python3.8/site-packages/IPython/core/ultratb.py\", line 1101, in get_records\n",
      "    return _fixed_getinnerframes(etb, number_of_lines_of_context, tb_offset)\n",
      "  File \"/Users/mosi/opt/anaconda3/lib/python3.8/site-packages/IPython/core/ultratb.py\", line 248, in wrapped\n",
      "    return f(*args, **kwargs)\n",
      "  File \"/Users/mosi/opt/anaconda3/lib/python3.8/site-packages/IPython/core/ultratb.py\", line 281, in _fixed_getinnerframes\n",
      "    records = fix_frame_records_filenames(inspect.getinnerframes(etb, context))\n",
      "  File \"/Users/mosi/opt/anaconda3/lib/python3.8/inspect.py\", line 1515, in getinnerframes\n",
      "    frameinfo = (tb.tb_frame,) + getframeinfo(tb, context)\n",
      "  File \"/Users/mosi/opt/anaconda3/lib/python3.8/inspect.py\", line 1473, in getframeinfo\n",
      "    filename = getsourcefile(frame) or getfile(frame)\n",
      "  File \"/Users/mosi/opt/anaconda3/lib/python3.8/inspect.py\", line 708, in getsourcefile\n",
      "    if getattr(getmodule(object, filename), '__loader__', None) is not None:\n",
      "  File \"/Users/mosi/opt/anaconda3/lib/python3.8/inspect.py\", line 737, in getmodule\n",
      "    file = getabsfile(object, _filename)\n",
      "  File \"/Users/mosi/opt/anaconda3/lib/python3.8/inspect.py\", line 721, in getabsfile\n",
      "    return os.path.normcase(os.path.abspath(_filename))\n",
      "  File \"/Users/mosi/opt/anaconda3/lib/python3.8/posixpath.py\", line 379, in abspath\n",
      "    cwd = os.getcwd()\n",
      "FileNotFoundError: [Errno 2] No such file or directory\n",
      "Traceback (most recent call last):\n",
      "  File \"/Users/mosi/opt/anaconda3/lib/python3.8/site-packages/IPython/core/interactiveshell.py\", line 3437, in run_code\n",
      "    exec(code_obj, self.user_global_ns, self.user_ns)\n",
      "  File \"<ipython-input-40-40f591368024>\", line 2, in <module>\n",
      "    lats = np.random.uniform(low=-90.000, high=90.000, size=1500)\n",
      "NameError: name 'np' is not defined\n",
      "\n",
      "During handling of the above exception, another exception occurred:\n",
      "\n",
      "Traceback (most recent call last):\n",
      "  File \"/Users/mosi/opt/anaconda3/lib/python3.8/site-packages/IPython/core/interactiveshell.py\", line 2061, in showtraceback\n",
      "    stb = value._render_traceback_()\n",
      "AttributeError: 'NameError' object has no attribute '_render_traceback_'\n",
      "\n",
      "During handling of the above exception, another exception occurred:\n",
      "\n",
      "Traceback (most recent call last):\n",
      "  File \"/Users/mosi/opt/anaconda3/lib/python3.8/site-packages/IPython/core/interactiveshell.py\", line 3357, in run_ast_nodes\n",
      "    if (await self.run_code(code, result,  async_=asy)):\n",
      "  File \"/Users/mosi/opt/anaconda3/lib/python3.8/site-packages/IPython/core/interactiveshell.py\", line 3454, in run_code\n",
      "    self.showtraceback(running_compiled_code=True)\n",
      "  File \"/Users/mosi/opt/anaconda3/lib/python3.8/site-packages/IPython/core/interactiveshell.py\", line 2063, in showtraceback\n",
      "    stb = self.InteractiveTB.structured_traceback(etype,\n",
      "  File \"/Users/mosi/opt/anaconda3/lib/python3.8/site-packages/IPython/core/ultratb.py\", line 1367, in structured_traceback\n",
      "    return FormattedTB.structured_traceback(\n",
      "  File \"/Users/mosi/opt/anaconda3/lib/python3.8/site-packages/IPython/core/ultratb.py\", line 1267, in structured_traceback\n",
      "    return VerboseTB.structured_traceback(\n",
      "  File \"/Users/mosi/opt/anaconda3/lib/python3.8/site-packages/IPython/core/ultratb.py\", line 1124, in structured_traceback\n",
      "    formatted_exception = self.format_exception_as_a_whole(etype, evalue, etb, number_of_lines_of_context,\n",
      "  File \"/Users/mosi/opt/anaconda3/lib/python3.8/site-packages/IPython/core/ultratb.py\", line 1082, in format_exception_as_a_whole\n",
      "    last_unique, recursion_repeat = find_recursion(orig_etype, evalue, records)\n",
      "  File \"/Users/mosi/opt/anaconda3/lib/python3.8/site-packages/IPython/core/ultratb.py\", line 382, in find_recursion\n",
      "    return len(records), 0\n",
      "TypeError: object of type 'NoneType' has no len()\n",
      "\n",
      "During handling of the above exception, another exception occurred:\n",
      "\n",
      "Traceback (most recent call last):\n",
      "  File \"/Users/mosi/opt/anaconda3/lib/python3.8/site-packages/IPython/core/interactiveshell.py\", line 2061, in showtraceback\n",
      "    stb = value._render_traceback_()\n",
      "AttributeError: 'TypeError' object has no attribute '_render_traceback_'\n",
      "\n",
      "During handling of the above exception, another exception occurred:\n",
      "\n",
      "Traceback (most recent call last):\n",
      "  File \"/Users/mosi/opt/anaconda3/lib/python3.8/site-packages/IPython/core/ultratb.py\", line 1101, in get_records\n",
      "    return _fixed_getinnerframes(etb, number_of_lines_of_context, tb_offset)\n",
      "  File \"/Users/mosi/opt/anaconda3/lib/python3.8/site-packages/IPython/core/ultratb.py\", line 248, in wrapped\n",
      "    return f(*args, **kwargs)\n",
      "  File \"/Users/mosi/opt/anaconda3/lib/python3.8/site-packages/IPython/core/ultratb.py\", line 281, in _fixed_getinnerframes\n",
      "    records = fix_frame_records_filenames(inspect.getinnerframes(etb, context))\n",
      "  File \"/Users/mosi/opt/anaconda3/lib/python3.8/inspect.py\", line 1515, in getinnerframes\n",
      "    frameinfo = (tb.tb_frame,) + getframeinfo(tb, context)\n",
      "  File \"/Users/mosi/opt/anaconda3/lib/python3.8/inspect.py\", line 1473, in getframeinfo\n",
      "    filename = getsourcefile(frame) or getfile(frame)\n",
      "  File \"/Users/mosi/opt/anaconda3/lib/python3.8/inspect.py\", line 708, in getsourcefile\n",
      "    if getattr(getmodule(object, filename), '__loader__', None) is not None:\n",
      "  File \"/Users/mosi/opt/anaconda3/lib/python3.8/inspect.py\", line 737, in getmodule\n",
      "    file = getabsfile(object, _filename)\n",
      "  File \"/Users/mosi/opt/anaconda3/lib/python3.8/inspect.py\", line 721, in getabsfile\n",
      "    return os.path.normcase(os.path.abspath(_filename))\n",
      "  File \"/Users/mosi/opt/anaconda3/lib/python3.8/posixpath.py\", line 379, in abspath\n",
      "    cwd = os.getcwd()\n",
      "FileNotFoundError: [Errno 2] No such file or directory\n",
      "Traceback (most recent call last):\n",
      "  File \"/Users/mosi/opt/anaconda3/lib/python3.8/site-packages/IPython/core/interactiveshell.py\", line 3437, in run_code\n",
      "    exec(code_obj, self.user_global_ns, self.user_ns)\n",
      "  File \"<ipython-input-40-40f591368024>\", line 2, in <module>\n",
      "    lats = np.random.uniform(low=-90.000, high=90.000, size=1500)\n",
      "NameError: name 'np' is not defined\n",
      "\n",
      "During handling of the above exception, another exception occurred:\n",
      "\n",
      "Traceback (most recent call last):\n",
      "  File \"/Users/mosi/opt/anaconda3/lib/python3.8/site-packages/IPython/core/interactiveshell.py\", line 2061, in showtraceback\n",
      "    stb = value._render_traceback_()\n",
      "AttributeError: 'NameError' object has no attribute '_render_traceback_'\n",
      "\n",
      "During handling of the above exception, another exception occurred:\n",
      "\n",
      "Traceback (most recent call last):\n",
      "  File \"/Users/mosi/opt/anaconda3/lib/python3.8/site-packages/IPython/core/interactiveshell.py\", line 3357, in run_ast_nodes\n",
      "    if (await self.run_code(code, result,  async_=asy)):\n",
      "  File \"/Users/mosi/opt/anaconda3/lib/python3.8/site-packages/IPython/core/interactiveshell.py\", line 3454, in run_code\n",
      "    self.showtraceback(running_compiled_code=True)\n",
      "  File \"/Users/mosi/opt/anaconda3/lib/python3.8/site-packages/IPython/core/interactiveshell.py\", line 2063, in showtraceback\n",
      "    stb = self.InteractiveTB.structured_traceback(etype,\n",
      "  File \"/Users/mosi/opt/anaconda3/lib/python3.8/site-packages/IPython/core/ultratb.py\", line 1367, in structured_traceback\n",
      "    return FormattedTB.structured_traceback(\n",
      "  File \"/Users/mosi/opt/anaconda3/lib/python3.8/site-packages/IPython/core/ultratb.py\", line 1267, in structured_traceback\n",
      "    return VerboseTB.structured_traceback(\n",
      "  File \"/Users/mosi/opt/anaconda3/lib/python3.8/site-packages/IPython/core/ultratb.py\", line 1124, in structured_traceback\n",
      "    formatted_exception = self.format_exception_as_a_whole(etype, evalue, etb, number_of_lines_of_context,\n",
      "  File \"/Users/mosi/opt/anaconda3/lib/python3.8/site-packages/IPython/core/ultratb.py\", line 1082, in format_exception_as_a_whole\n",
      "    last_unique, recursion_repeat = find_recursion(orig_etype, evalue, records)\n",
      "  File \"/Users/mosi/opt/anaconda3/lib/python3.8/site-packages/IPython/core/ultratb.py\", line 382, in find_recursion\n",
      "    return len(records), 0\n",
      "TypeError: object of type 'NoneType' has no len()\n",
      "\n",
      "During handling of the above exception, another exception occurred:\n",
      "\n",
      "Traceback (most recent call last):\n",
      "  File \"/Users/mosi/opt/anaconda3/lib/python3.8/site-packages/IPython/core/interactiveshell.py\", line 2061, in showtraceback\n",
      "    stb = value._render_traceback_()\n",
      "AttributeError: 'TypeError' object has no attribute '_render_traceback_'\n",
      "\n",
      "During handling of the above exception, another exception occurred:\n",
      "\n",
      "Traceback (most recent call last):\n",
      "  File \"/Users/mosi/opt/anaconda3/lib/python3.8/site-packages/IPython/core/interactiveshell.py\", line 2940, in _run_cell\n",
      "    return runner(coro)\n",
      "  File \"/Users/mosi/opt/anaconda3/lib/python3.8/site-packages/IPython/core/async_helpers.py\", line 68, in _pseudo_sync_runner\n",
      "    coro.send(None)\n",
      "  File \"/Users/mosi/opt/anaconda3/lib/python3.8/site-packages/IPython/core/interactiveshell.py\", line 3165, in run_cell_async\n",
      "    has_raised = await self.run_ast_nodes(code_ast.body, cell_name,\n",
      "  File \"/Users/mosi/opt/anaconda3/lib/python3.8/site-packages/IPython/core/interactiveshell.py\", line 3376, in run_ast_nodes\n",
      "    self.showtraceback()\n",
      "  File \"/Users/mosi/opt/anaconda3/lib/python3.8/site-packages/IPython/core/interactiveshell.py\", line 2063, in showtraceback\n",
      "    stb = self.InteractiveTB.structured_traceback(etype,\n",
      "  File \"/Users/mosi/opt/anaconda3/lib/python3.8/site-packages/IPython/core/ultratb.py\", line 1367, in structured_traceback\n",
      "    return FormattedTB.structured_traceback(\n",
      "  File \"/Users/mosi/opt/anaconda3/lib/python3.8/site-packages/IPython/core/ultratb.py\", line 1267, in structured_traceback\n",
      "    return VerboseTB.structured_traceback(\n",
      "  File \"/Users/mosi/opt/anaconda3/lib/python3.8/site-packages/IPython/core/ultratb.py\", line 1142, in structured_traceback\n",
      "    formatted_exceptions += self.format_exception_as_a_whole(etype, evalue, etb, lines_of_context,\n",
      "  File \"/Users/mosi/opt/anaconda3/lib/python3.8/site-packages/IPython/core/ultratb.py\", line 1082, in format_exception_as_a_whole\n",
      "    last_unique, recursion_repeat = find_recursion(orig_etype, evalue, records)\n",
      "  File \"/Users/mosi/opt/anaconda3/lib/python3.8/site-packages/IPython/core/ultratb.py\", line 382, in find_recursion\n",
      "    return len(records), 0\n",
      "TypeError: object of type 'NoneType' has no len()\n",
      "\n",
      "During handling of the above exception, another exception occurred:\n",
      "\n",
      "Traceback (most recent call last):\n",
      "  File \"/Users/mosi/opt/anaconda3/lib/python3.8/site-packages/IPython/core/interactiveshell.py\", line 2061, in showtraceback\n",
      "    stb = value._render_traceback_()\n",
      "AttributeError: 'TypeError' object has no attribute '_render_traceback_'\n",
      "\n",
      "During handling of the above exception, another exception occurred:\n",
      "\n",
      "Traceback (most recent call last):\n",
      "  File \"/Users/mosi/opt/anaconda3/lib/python3.8/site-packages/IPython/core/ultratb.py\", line 1101, in get_records\n",
      "    return _fixed_getinnerframes(etb, number_of_lines_of_context, tb_offset)\n",
      "  File \"/Users/mosi/opt/anaconda3/lib/python3.8/site-packages/IPython/core/ultratb.py\", line 248, in wrapped\n",
      "    return f(*args, **kwargs)\n",
      "  File \"/Users/mosi/opt/anaconda3/lib/python3.8/site-packages/IPython/core/ultratb.py\", line 281, in _fixed_getinnerframes\n",
      "    records = fix_frame_records_filenames(inspect.getinnerframes(etb, context))\n",
      "  File \"/Users/mosi/opt/anaconda3/lib/python3.8/inspect.py\", line 1515, in getinnerframes\n",
      "    frameinfo = (tb.tb_frame,) + getframeinfo(tb, context)\n",
      "  File \"/Users/mosi/opt/anaconda3/lib/python3.8/inspect.py\", line 1473, in getframeinfo\n",
      "    filename = getsourcefile(frame) or getfile(frame)\n",
      "  File \"/Users/mosi/opt/anaconda3/lib/python3.8/inspect.py\", line 708, in getsourcefile\n",
      "    if getattr(getmodule(object, filename), '__loader__', None) is not None:\n",
      "  File \"/Users/mosi/opt/anaconda3/lib/python3.8/inspect.py\", line 737, in getmodule\n",
      "    file = getabsfile(object, _filename)\n",
      "  File \"/Users/mosi/opt/anaconda3/lib/python3.8/inspect.py\", line 721, in getabsfile\n",
      "    return os.path.normcase(os.path.abspath(_filename))\n",
      "  File \"/Users/mosi/opt/anaconda3/lib/python3.8/posixpath.py\", line 379, in abspath\n",
      "    cwd = os.getcwd()\n",
      "FileNotFoundError: [Errno 2] No such file or directory\n"
     ]
    }
   ],
   "source": [
    "# Create a set of random latitude and longitude combinations.\n",
    "lats = np.random.uniform(low=-90.000, high=90.000, size=1500)\n",
    "lngs = np.random.uniform(low=-180.000, high=180.000, size=1500)\n",
    "lat_lngs = zip(lats, lngs)\n",
    "lat_lngs"
   ]
  },
  {
   "cell_type": "code",
   "execution_count": 1,
   "id": "4c73868b",
   "metadata": {},
   "outputs": [
    {
     "data": {
      "text/plain": [
       "1637829456.910468"
      ]
     },
     "execution_count": 1,
     "metadata": {},
     "output_type": "execute_result"
    }
   ],
   "source": [
    "# Import the time module.\n",
    "import time\n",
    "# Get today's date in seconds.\n",
    "today = time.time()\n",
    "today"
   ]
  },
  {
   "cell_type": "code",
   "execution_count": null,
   "id": "54c0270f",
   "metadata": {},
   "outputs": [],
   "source": []
  }
 ],
 "metadata": {
  "kernelspec": {
   "display_name": "PythonData",
   "language": "python",
   "name": "pythondata"
  },
  "language_info": {
   "codemirror_mode": {
    "name": "ipython",
    "version": 3
   },
   "file_extension": ".py",
   "mimetype": "text/x-python",
   "name": "python",
   "nbconvert_exporter": "python",
   "pygments_lexer": "ipython3",
   "version": "3.8.8"
  }
 },
 "nbformat": 4,
 "nbformat_minor": 5
}
