{
 "cells": [
  {
   "cell_type": "code",
   "execution_count": 30,
   "id": "e140d8b8",
   "metadata": {},
   "outputs": [],
   "source": [
    "# Import the dependencies.\n",
    "import pandas as pd\n",
    "import matplotlib.pyplot as plt\n",
    "import numpy as np"
   ]
  },
  {
   "cell_type": "code",
   "execution_count": 42,
   "id": "3da90e1d",
   "metadata": {},
   "outputs": [
    {
     "data": {
      "text/plain": [
       "<zip at 0x7fb448040740>"
      ]
     },
     "execution_count": 42,
     "metadata": {},
     "output_type": "execute_result"
    }
   ],
   "source": [
    "# Create a set of random latitude and longitude combinations.\n",
    "lats = np.random.uniform(low=-90.000, high=90.000, size=1500)\n",
    "lngs = np.random.uniform(low=-180.000, high=180.000, size=1500)\n",
    "lat_lngs = zip(lats, lngs)\n",
    "lat_lngs"
   ]
  },
  {
   "cell_type": "code",
   "execution_count": 43,
   "id": "389fd1d7",
   "metadata": {},
   "outputs": [],
   "source": [
    "# Add the latitudes and longitudes to a list.\n",
    "coordinates = list(lat_lngs)"
   ]
  },
  {
   "cell_type": "code",
   "execution_count": 44,
   "id": "df757e36",
   "metadata": {},
   "outputs": [],
   "source": [
    "# Use the citipy module to determine city based on latitude and longitude.\n",
    "from citipy import citipy"
   ]
  },
  {
   "cell_type": "code",
   "execution_count": 45,
   "id": "c824df0c",
   "metadata": {},
   "outputs": [
    {
     "data": {
      "text/plain": [
       "613"
      ]
     },
     "execution_count": 45,
     "metadata": {},
     "output_type": "execute_result"
    }
   ],
   "source": [
    "# Create a list for holding the cities.\n",
    "cities = []\n",
    "# Identify the nearest city for each latitude and longitude combination.\n",
    "for coordinate in coordinates:\n",
    "    city = citipy.nearest_city(coordinate[0], coordinate[1]).city_name\n",
    "\n",
    "    # If the city is unique, then we will add it to the cities list.\n",
    "    if city not in cities:\n",
    "        cities.append(city)\n",
    "# Print the city count to confirm sufficient count.\n",
    "len(cities)"
   ]
  },
  {
   "cell_type": "code",
   "execution_count": 46,
   "id": "8c10b937",
   "metadata": {},
   "outputs": [],
   "source": [
    "# Import the time library and the datetime module from the datetime library \n",
    "import time\n",
    "from datetime import datetime"
   ]
  },
  {
   "cell_type": "code",
   "execution_count": 47,
   "id": "54574a9a",
   "metadata": {},
   "outputs": [
    {
     "name": "stdout",
     "output_type": "stream",
     "text": [
      "Beginning Data Retrieval     \n",
      "-----------------------------\n"
     ]
    }
   ],
   "source": [
    "# Create an empty list to hold the weather data.\n",
    "city_data = []\n",
    "# Print the beginning of the logging.\n",
    "print(\"Beginning Data Retrieval     \")\n",
    "print(\"-----------------------------\")\n",
    "\n",
    "# Create counters.\n",
    "record_count = 1\n",
    "set_count = 1"
   ]
  },
  {
   "cell_type": "code",
   "execution_count": null,
   "id": "1c29321d",
   "metadata": {},
   "outputs": [
    {
     "name": "stderr",
     "output_type": "stream",
     "text": [
      "ERROR:root:Internal Python error in the inspect module.\n",
      "Below is the traceback from this internal error.\n",
      "\n",
      "ERROR:root:Internal Python error in the inspect module.\n",
      "Below is the traceback from this internal error.\n",
      "\n",
      "ERROR:root:Internal Python error in the inspect module.\n",
      "Below is the traceback from this internal error.\n",
      "\n"
     ]
    },
    {
     "name": "stdout",
     "output_type": "stream",
     "text": [
      "Traceback (most recent call last):\n",
      "  File \"/Users/mosi/opt/anaconda3/lib/python3.8/site-packages/IPython/core/interactiveshell.py\", line 3437, in run_code\n",
      "    exec(code_obj, self.user_global_ns, self.user_ns)\n",
      "  File \"<ipython-input-48-a78dda81dfab>\", line 11, in <module>\n",
      "    city_url = url + \"&q=\" + city.replace(\" \",\"+\")\n",
      "NameError: name 'url' is not defined\n",
      "\n",
      "During handling of the above exception, another exception occurred:\n",
      "\n",
      "Traceback (most recent call last):\n",
      "  File \"/Users/mosi/opt/anaconda3/lib/python3.8/site-packages/IPython/core/interactiveshell.py\", line 2061, in showtraceback\n",
      "    stb = value._render_traceback_()\n",
      "AttributeError: 'NameError' object has no attribute '_render_traceback_'\n",
      "\n",
      "During handling of the above exception, another exception occurred:\n",
      "\n",
      "Traceback (most recent call last):\n",
      "  File \"/Users/mosi/opt/anaconda3/lib/python3.8/site-packages/IPython/core/ultratb.py\", line 1101, in get_records\n",
      "    return _fixed_getinnerframes(etb, number_of_lines_of_context, tb_offset)\n",
      "  File \"/Users/mosi/opt/anaconda3/lib/python3.8/site-packages/IPython/core/ultratb.py\", line 248, in wrapped\n",
      "    return f(*args, **kwargs)\n",
      "  File \"/Users/mosi/opt/anaconda3/lib/python3.8/site-packages/IPython/core/ultratb.py\", line 281, in _fixed_getinnerframes\n",
      "    records = fix_frame_records_filenames(inspect.getinnerframes(etb, context))\n",
      "  File \"/Users/mosi/opt/anaconda3/lib/python3.8/inspect.py\", line 1515, in getinnerframes\n",
      "    frameinfo = (tb.tb_frame,) + getframeinfo(tb, context)\n",
      "  File \"/Users/mosi/opt/anaconda3/lib/python3.8/inspect.py\", line 1473, in getframeinfo\n",
      "    filename = getsourcefile(frame) or getfile(frame)\n",
      "  File \"/Users/mosi/opt/anaconda3/lib/python3.8/inspect.py\", line 708, in getsourcefile\n",
      "    if getattr(getmodule(object, filename), '__loader__', None) is not None:\n",
      "  File \"/Users/mosi/opt/anaconda3/lib/python3.8/inspect.py\", line 737, in getmodule\n",
      "    file = getabsfile(object, _filename)\n",
      "  File \"/Users/mosi/opt/anaconda3/lib/python3.8/inspect.py\", line 721, in getabsfile\n",
      "    return os.path.normcase(os.path.abspath(_filename))\n",
      "  File \"/Users/mosi/opt/anaconda3/lib/python3.8/posixpath.py\", line 379, in abspath\n",
      "    cwd = os.getcwd()\n",
      "FileNotFoundError: [Errno 2] No such file or directory\n",
      "ERROR! Session/line number was not unique in database. History logging moved to new session 43\n",
      "Traceback (most recent call last):\n",
      "  File \"/Users/mosi/opt/anaconda3/lib/python3.8/site-packages/IPython/core/interactiveshell.py\", line 3437, in run_code\n",
      "    exec(code_obj, self.user_global_ns, self.user_ns)\n",
      "  File \"<ipython-input-48-a78dda81dfab>\", line 11, in <module>\n",
      "    city_url = url + \"&q=\" + city.replace(\" \",\"+\")\n",
      "NameError: name 'url' is not defined\n",
      "\n",
      "During handling of the above exception, another exception occurred:\n",
      "\n",
      "Traceback (most recent call last):\n",
      "  File \"/Users/mosi/opt/anaconda3/lib/python3.8/site-packages/IPython/core/interactiveshell.py\", line 2061, in showtraceback\n",
      "    stb = value._render_traceback_()\n",
      "AttributeError: 'NameError' object has no attribute '_render_traceback_'\n",
      "\n",
      "During handling of the above exception, another exception occurred:\n",
      "\n",
      "Traceback (most recent call last):\n",
      "  File \"/Users/mosi/opt/anaconda3/lib/python3.8/site-packages/IPython/core/interactiveshell.py\", line 3357, in run_ast_nodes\n",
      "    if (await self.run_code(code, result,  async_=asy)):\n",
      "  File \"/Users/mosi/opt/anaconda3/lib/python3.8/site-packages/IPython/core/interactiveshell.py\", line 3454, in run_code\n",
      "    self.showtraceback(running_compiled_code=True)\n",
      "  File \"/Users/mosi/opt/anaconda3/lib/python3.8/site-packages/IPython/core/interactiveshell.py\", line 2063, in showtraceback\n",
      "    stb = self.InteractiveTB.structured_traceback(etype,\n",
      "  File \"/Users/mosi/opt/anaconda3/lib/python3.8/site-packages/IPython/core/ultratb.py\", line 1367, in structured_traceback\n",
      "    return FormattedTB.structured_traceback(\n",
      "  File \"/Users/mosi/opt/anaconda3/lib/python3.8/site-packages/IPython/core/ultratb.py\", line 1267, in structured_traceback\n",
      "    return VerboseTB.structured_traceback(\n",
      "  File \"/Users/mosi/opt/anaconda3/lib/python3.8/site-packages/IPython/core/ultratb.py\", line 1124, in structured_traceback\n",
      "    formatted_exception = self.format_exception_as_a_whole(etype, evalue, etb, number_of_lines_of_context,\n",
      "  File \"/Users/mosi/opt/anaconda3/lib/python3.8/site-packages/IPython/core/ultratb.py\", line 1082, in format_exception_as_a_whole\n",
      "    last_unique, recursion_repeat = find_recursion(orig_etype, evalue, records)\n",
      "  File \"/Users/mosi/opt/anaconda3/lib/python3.8/site-packages/IPython/core/ultratb.py\", line 382, in find_recursion\n",
      "    return len(records), 0\n",
      "TypeError: object of type 'NoneType' has no len()\n",
      "\n",
      "During handling of the above exception, another exception occurred:\n",
      "\n",
      "Traceback (most recent call last):\n",
      "  File \"/Users/mosi/opt/anaconda3/lib/python3.8/site-packages/IPython/core/interactiveshell.py\", line 2061, in showtraceback\n",
      "    stb = value._render_traceback_()\n",
      "AttributeError: 'TypeError' object has no attribute '_render_traceback_'\n",
      "\n",
      "During handling of the above exception, another exception occurred:\n",
      "\n",
      "Traceback (most recent call last):\n",
      "  File \"/Users/mosi/opt/anaconda3/lib/python3.8/site-packages/IPython/core/ultratb.py\", line 1101, in get_records\n",
      "    return _fixed_getinnerframes(etb, number_of_lines_of_context, tb_offset)\n",
      "  File \"/Users/mosi/opt/anaconda3/lib/python3.8/site-packages/IPython/core/ultratb.py\", line 248, in wrapped\n",
      "    return f(*args, **kwargs)\n",
      "  File \"/Users/mosi/opt/anaconda3/lib/python3.8/site-packages/IPython/core/ultratb.py\", line 281, in _fixed_getinnerframes\n",
      "    records = fix_frame_records_filenames(inspect.getinnerframes(etb, context))\n",
      "  File \"/Users/mosi/opt/anaconda3/lib/python3.8/inspect.py\", line 1515, in getinnerframes\n",
      "    frameinfo = (tb.tb_frame,) + getframeinfo(tb, context)\n",
      "  File \"/Users/mosi/opt/anaconda3/lib/python3.8/inspect.py\", line 1473, in getframeinfo\n",
      "    filename = getsourcefile(frame) or getfile(frame)\n",
      "  File \"/Users/mosi/opt/anaconda3/lib/python3.8/inspect.py\", line 708, in getsourcefile\n",
      "    if getattr(getmodule(object, filename), '__loader__', None) is not None:\n",
      "  File \"/Users/mosi/opt/anaconda3/lib/python3.8/inspect.py\", line 737, in getmodule\n",
      "    file = getabsfile(object, _filename)\n",
      "  File \"/Users/mosi/opt/anaconda3/lib/python3.8/inspect.py\", line 721, in getabsfile\n",
      "    return os.path.normcase(os.path.abspath(_filename))\n",
      "  File \"/Users/mosi/opt/anaconda3/lib/python3.8/posixpath.py\", line 379, in abspath\n",
      "    cwd = os.getcwd()\n",
      "FileNotFoundError: [Errno 2] No such file or directory\n",
      "Traceback (most recent call last):\n",
      "  File \"/Users/mosi/opt/anaconda3/lib/python3.8/site-packages/IPython/core/interactiveshell.py\", line 3437, in run_code\n",
      "    exec(code_obj, self.user_global_ns, self.user_ns)\n",
      "  File \"<ipython-input-48-a78dda81dfab>\", line 11, in <module>\n",
      "    city_url = url + \"&q=\" + city.replace(\" \",\"+\")\n",
      "NameError: name 'url' is not defined\n",
      "\n",
      "During handling of the above exception, another exception occurred:\n",
      "\n",
      "Traceback (most recent call last):\n",
      "  File \"/Users/mosi/opt/anaconda3/lib/python3.8/site-packages/IPython/core/interactiveshell.py\", line 2061, in showtraceback\n",
      "    stb = value._render_traceback_()\n",
      "AttributeError: 'NameError' object has no attribute '_render_traceback_'\n",
      "\n",
      "During handling of the above exception, another exception occurred:\n",
      "\n",
      "Traceback (most recent call last):\n",
      "  File \"/Users/mosi/opt/anaconda3/lib/python3.8/site-packages/IPython/core/interactiveshell.py\", line 3357, in run_ast_nodes\n",
      "    if (await self.run_code(code, result,  async_=asy)):\n",
      "  File \"/Users/mosi/opt/anaconda3/lib/python3.8/site-packages/IPython/core/interactiveshell.py\", line 3454, in run_code\n",
      "    self.showtraceback(running_compiled_code=True)\n",
      "  File \"/Users/mosi/opt/anaconda3/lib/python3.8/site-packages/IPython/core/interactiveshell.py\", line 2063, in showtraceback\n",
      "    stb = self.InteractiveTB.structured_traceback(etype,\n",
      "  File \"/Users/mosi/opt/anaconda3/lib/python3.8/site-packages/IPython/core/ultratb.py\", line 1367, in structured_traceback\n",
      "    return FormattedTB.structured_traceback(\n",
      "  File \"/Users/mosi/opt/anaconda3/lib/python3.8/site-packages/IPython/core/ultratb.py\", line 1267, in structured_traceback\n",
      "    return VerboseTB.structured_traceback(\n",
      "  File \"/Users/mosi/opt/anaconda3/lib/python3.8/site-packages/IPython/core/ultratb.py\", line 1124, in structured_traceback\n",
      "    formatted_exception = self.format_exception_as_a_whole(etype, evalue, etb, number_of_lines_of_context,\n",
      "  File \"/Users/mosi/opt/anaconda3/lib/python3.8/site-packages/IPython/core/ultratb.py\", line 1082, in format_exception_as_a_whole\n",
      "    last_unique, recursion_repeat = find_recursion(orig_etype, evalue, records)\n",
      "  File \"/Users/mosi/opt/anaconda3/lib/python3.8/site-packages/IPython/core/ultratb.py\", line 382, in find_recursion\n",
      "    return len(records), 0\n",
      "TypeError: object of type 'NoneType' has no len()\n",
      "\n",
      "During handling of the above exception, another exception occurred:\n",
      "\n",
      "Traceback (most recent call last):\n",
      "  File \"/Users/mosi/opt/anaconda3/lib/python3.8/site-packages/IPython/core/interactiveshell.py\", line 2061, in showtraceback\n",
      "    stb = value._render_traceback_()\n",
      "AttributeError: 'TypeError' object has no attribute '_render_traceback_'\n",
      "\n",
      "During handling of the above exception, another exception occurred:\n",
      "\n",
      "Traceback (most recent call last):\n",
      "  File \"/Users/mosi/opt/anaconda3/lib/python3.8/site-packages/IPython/core/interactiveshell.py\", line 2940, in _run_cell\n",
      "    return runner(coro)\n",
      "  File \"/Users/mosi/opt/anaconda3/lib/python3.8/site-packages/IPython/core/async_helpers.py\", line 68, in _pseudo_sync_runner\n",
      "    coro.send(None)\n",
      "  File \"/Users/mosi/opt/anaconda3/lib/python3.8/site-packages/IPython/core/interactiveshell.py\", line 3165, in run_cell_async\n",
      "    has_raised = await self.run_ast_nodes(code_ast.body, cell_name,\n",
      "  File \"/Users/mosi/opt/anaconda3/lib/python3.8/site-packages/IPython/core/interactiveshell.py\", line 3376, in run_ast_nodes\n",
      "    self.showtraceback()\n",
      "  File \"/Users/mosi/opt/anaconda3/lib/python3.8/site-packages/IPython/core/interactiveshell.py\", line 2063, in showtraceback\n",
      "    stb = self.InteractiveTB.structured_traceback(etype,\n",
      "  File \"/Users/mosi/opt/anaconda3/lib/python3.8/site-packages/IPython/core/ultratb.py\", line 1367, in structured_traceback\n",
      "    return FormattedTB.structured_traceback(\n",
      "  File \"/Users/mosi/opt/anaconda3/lib/python3.8/site-packages/IPython/core/ultratb.py\", line 1267, in structured_traceback\n",
      "    return VerboseTB.structured_traceback(\n",
      "  File \"/Users/mosi/opt/anaconda3/lib/python3.8/site-packages/IPython/core/ultratb.py\", line 1142, in structured_traceback\n",
      "    formatted_exceptions += self.format_exception_as_a_whole(etype, evalue, etb, lines_of_context,\n",
      "  File \"/Users/mosi/opt/anaconda3/lib/python3.8/site-packages/IPython/core/ultratb.py\", line 1082, in format_exception_as_a_whole\n",
      "    last_unique, recursion_repeat = find_recursion(orig_etype, evalue, records)\n",
      "  File \"/Users/mosi/opt/anaconda3/lib/python3.8/site-packages/IPython/core/ultratb.py\", line 382, in find_recursion\n",
      "    return len(records), 0\n",
      "TypeError: object of type 'NoneType' has no len()\n",
      "\n",
      "During handling of the above exception, another exception occurred:\n",
      "\n",
      "Traceback (most recent call last):\n",
      "  File \"/Users/mosi/opt/anaconda3/lib/python3.8/site-packages/IPython/core/interactiveshell.py\", line 2061, in showtraceback\n",
      "    stb = value._render_traceback_()\n",
      "AttributeError: 'TypeError' object has no attribute '_render_traceback_'\n",
      "\n",
      "During handling of the above exception, another exception occurred:\n",
      "\n",
      "Traceback (most recent call last):\n",
      "  File \"/Users/mosi/opt/anaconda3/lib/python3.8/site-packages/IPython/core/ultratb.py\", line 1101, in get_records\n",
      "    return _fixed_getinnerframes(etb, number_of_lines_of_context, tb_offset)\n",
      "  File \"/Users/mosi/opt/anaconda3/lib/python3.8/site-packages/IPython/core/ultratb.py\", line 248, in wrapped\n",
      "    return f(*args, **kwargs)\n",
      "  File \"/Users/mosi/opt/anaconda3/lib/python3.8/site-packages/IPython/core/ultratb.py\", line 281, in _fixed_getinnerframes\n",
      "    records = fix_frame_records_filenames(inspect.getinnerframes(etb, context))\n",
      "  File \"/Users/mosi/opt/anaconda3/lib/python3.8/inspect.py\", line 1515, in getinnerframes\n",
      "    frameinfo = (tb.tb_frame,) + getframeinfo(tb, context)\n",
      "  File \"/Users/mosi/opt/anaconda3/lib/python3.8/inspect.py\", line 1473, in getframeinfo\n",
      "    filename = getsourcefile(frame) or getfile(frame)\n",
      "  File \"/Users/mosi/opt/anaconda3/lib/python3.8/inspect.py\", line 708, in getsourcefile\n",
      "    if getattr(getmodule(object, filename), '__loader__', None) is not None:\n",
      "  File \"/Users/mosi/opt/anaconda3/lib/python3.8/inspect.py\", line 737, in getmodule\n",
      "    file = getabsfile(object, _filename)\n",
      "  File \"/Users/mosi/opt/anaconda3/lib/python3.8/inspect.py\", line 721, in getabsfile\n",
      "    return os.path.normcase(os.path.abspath(_filename))\n",
      "  File \"/Users/mosi/opt/anaconda3/lib/python3.8/posixpath.py\", line 379, in abspath\n",
      "    cwd = os.getcwd()\n",
      "FileNotFoundError: [Errno 2] No such file or directory\n"
     ]
    }
   ],
   "source": [
    "# Loop through all the cities in the list.\n",
    "for i, city in enumerate(cities):\n",
    "\n",
    "    # Group cities in sets of 50 for logging purposes.\n",
    "    if (i % 50 == 0 and i >= 50):\n",
    "        set_count += 1\n",
    "        record_count = 1\n",
    "        time.sleep(60)\n",
    "\n",
    "    # Create endpoint URL with each city.\n",
    "    city_url = url + \"&q=\" + city.replace(\" \",\"+\")\n",
    "\n",
    "    # Log the URL, record, and set numbers and the city.\n",
    "    print(f\"Processing Record {record_count} of Set {set_count} | {city}\")\n",
    "    # Add 1 to the record count.\n",
    "    record_count += 1\n",
    "# Run an API request for each of the cities.\n",
    "    try:\n",
    "        # Parse the JSON and retrieve data.\n",
    "        city_weather = requests.get(city_url).json()\n",
    "        # Parse out the needed data.\n",
    "        city_lat = city_weather[\"coord\"][\"lat\"]\n",
    "        city_lng = city_weather[\"coord\"][\"lon\"]\n",
    "        city_max_temp = city_weather[\"main\"][\"temp_max\"]\n",
    "        city_humidity = city_weather[\"main\"][\"humidity\"]\n",
    "        city_clouds = city_weather[\"clouds\"][\"all\"]\n",
    "        city_wind = city_weather[\"wind\"][\"speed\"]\n",
    "        city_country = city_weather[\"sys\"][\"country\"]\n",
    "        # Convert the date to ISO standard.\n",
    "        city_date = datetime.utcfromtimestamp(city_weather[\"dt\"]).strftime('%Y-%m-%d %H:%M:%S')\n",
    "        # Append the city information into city_data list.\n",
    "        city_data.append({\"City\": city.title(),\n",
    "                          \"Lat\": city_lat,\n",
    "                          \"Lng\": city_lng,\n",
    "                          \"Max Temp\": city_max_temp,\n",
    "                          \"Humidity\": city_humidity,\n",
    "                          \"Cloudiness\": city_clouds,\n",
    "                          \"Wind Speed\": city_wind,\n",
    "                          \"Country\": city_country,\n",
    "                          \"Date\": city_date})\n",
    "\n",
    "# If an error is experienced, skip the city.\n",
    "    except:\n",
    "        print(\"City not found. Skipping...\")\n",
    "        pass\n",
    "\n",
    "# Indicate that Data Loading is complete.\n",
    "print(\"-----------------------------\")\n",
    "print(\"Data Retrieval Complete      \")\n",
    "print(\"-----------------------------\")"
   ]
  },
  {
   "cell_type": "code",
   "execution_count": null,
   "id": "f21586db",
   "metadata": {},
   "outputs": [],
   "source": []
  },
  {
   "cell_type": "code",
   "execution_count": null,
   "id": "c778eb59",
   "metadata": {},
   "outputs": [],
   "source": []
  },
  {
   "cell_type": "code",
   "execution_count": null,
   "id": "58f8756c",
   "metadata": {},
   "outputs": [],
   "source": []
  }
 ],
 "metadata": {
  "kernelspec": {
   "display_name": "PythonData",
   "language": "python",
   "name": "pythondata"
  },
  "language_info": {
   "codemirror_mode": {
    "name": "ipython",
    "version": 3
   },
   "file_extension": ".py",
   "mimetype": "text/x-python",
   "name": "python",
   "nbconvert_exporter": "python",
   "pygments_lexer": "ipython3",
   "version": "3.8.8"
  }
 },
 "nbformat": 4,
 "nbformat_minor": 5
}
